Workbook

Sheet README
A1: MEDIFIN · Case #01 Toy Kingdom Inc. — Decision Set (đã khớp USER_FLOW gốc)
A2: 👉 Xem tất cả ma trận tại sheet DECISION_MATRIX (tab đỏ, ngay sau README).
A4: 1. Cách dùng nhanh
A5: Bước 1: Mở Scorecard → đổi các ô dropdown màu vàng (mỗi cột = một người chơi).
A6: Bước 2: Xem điểm từng phần, điểm tổng, Uy tín, điểm Tài chính / Quản trị và kết cục 3×3 ở Scorecard; hoặc xem Comparison để so sánh song song.
A7: Bước 3: Muốn chỉnh cân bằng → sửa các ô chữ xanh (blue) trong sheet S*, M* và Config; mọi điểm tự tính lại.
A9: 2. Bản đồ sheet ↔ màn hình (theo USER_FLOW gốc)
A10: Màn hình | B10: Sheet | C10: Nội dung
A11: Màn 0–1 | B11: Case_Facts | C11: Tổng quan, bí mật nền, 3 trục theo dõi + các giả định thiết kế.
A12: Màn 4 | B12: Financials | C12: BCTC FY2024–26, chỉ số vận hành, snapshot bảng cân đối, đòn bẩy.
A13: Màn 2 | B13: S2_Files + M1 + M2 | C13: 7 hồ sơ HS-A..G (chọn 3); M1: hồ sơ × CH1 (cùng khu vực chỉ =1); M2: hồ sơ × CH2.
A14: Màn 3 | B14: S3_Questions | C14: 7 câu hỏi CH1-A..G (chọn 2), điểm bề mặt.
A15: Màn 5 | B15: S5_FinalQ | C15: 7 câu hỏi CH2-A..G (chọn 1).
A16: Màn 6 | B16: S6_Diagnosis + M3 | C16: 6 chẩn đoán CD-A..F (chọn 1), điều kiện CD-F, M3: chẩn đoán × hồ sơ.
A17: Màn 7 | B17: S7_Treatment + M4 | C17: 6 phác đồ PD-A..F (chọn 1), điều kiện Uy tín (PD-A ≥TB, PD-F Cao), M4: chẩn đoán × phác đồ.
A18: Màn 8 | B18: S8_Timing + M5 | C18: 4 thời điểm TG-A..D; M5: phác đồ × thời điểm.
A19: Màn 9 | B19: S9_Stakeholders + M6 | C19: 7 nhóm (chọn 3); M6: phác đồ × nhóm; điểm Quản trị của Governance & Family.
A20: Màn 10 | B20: S10_Consequence | C20: M7/M8/M9 = công thức điểm Tài chính; bảng 14 diễn biến (7 gốc + 4 phản bác chẩn đoán sai + 3 hệ quả nhóm ưu tiên) và dữ liệu mới biện minh Tái khám.
A21: Màn 11 | B21: S11_Reassess | C21: Giữ / Đổi chẩn đoán / Đổi phác đồ, chi phí Uy tín.
... A23: Hỗ trợ | B23: Config, Lists | C23: Ngưỡng, trọng số, điểm Uy tín; dropdown tự sinh.
A25: 3. Công thức chấm điểm
A26: Kết cục (theo USER_FLOW gốc) | B26: Điểm Tài chính = M7 (PD×TG) + M8/M9 (nhóm ưu tiên). Tier: Ổn định / Mong manh (1–3) / Sụp đổ (≤0). Điểm Quản trị = +1 mở HS-G; +2/−1 Governance & Family; −1 mỗi lần mất Uy tín; −2 nếu Sụp đổ tài chính; −1 nếu PD-D chưa mở HS-E. Tier: ≥3 Đoàn kết · 0–2 Chia rẽ · <0 Mất kiểm soát. → ô 3×3.
A27: Uy tín | B27: Thấp / Trung bình / Cao. Không đổi ô kết cục, đổi cách mô tả. Là điều kiện mở PD-A và PD-F; thay đổi bởi CD-F thiếu điều kiện, TG-C thất bại, đổi thiếu dữ liệu mới.
A28: Lớp điểm /100 (bổ sung) | B28: Investigation, Diagnosis, Treatment, Execution, Reassessment (0–100) và Overall (20/25/20/20/15%) để so sánh người chơi.
A30: 4. Đã chốt theo USER_FLOW bản sửa (không còn là giả định)
A31: • Ngưỡng 'Ổn định tài chính' = ≥4 (Config → fr_stable). Ngưỡng ≥5 trong bản nháp đầu không đạt được (điểm tối đa chỉ +4) — đội đã chốt lại ≥4, có ghi chú ngay trong USER_FLOW Màn 12.
A32: • 6 chẩn đoán CD-A..F đổi tên theo khung '6 tầng vấn đề' (Áp lực Cạnh tranh, Nút thắt Vận hành, Biểu hiện Thanh khoản, Nguyên nhân Cấu trúc, Áp lực Danh mục, Đa yếu tố) — không còn khung đúng/sai ngầm định.
A33: • Màn 10 có đủ 14 diễn biến: 7 gốc + 4 sự kiện phản bác trực tiếp cho CD-A/B/C/E + 3 hệ quả quan sát được cho Employees/Customers/Landlords.
A35: 5. Điểm cần bạn xác nhận (case gốc không nêu)
A36: • Uy tín khởi điểm, quy tắc tăng (+1 chẩn đoán có căn cứ, +1 điều tra hiệu quả) và cách xác định 'refinance thử thành công / có dữ liệu mới' là GIẢ ĐỊNH của file — chỉnh ở Config và S10.
A37: • CD-D 'Nguyên nhân Cấu trúc' được dùng làm MỐC CHẤM ĐIỂM Treatment (không phải tuyên bố '5 chẩn đoán kia sai') — nếu nhóm muốn đổi mốc, sửa Config → true_dx và bảng M3, M4.
A38: • Các nhóm ưu tiên ở Màn 9 không có mã trong case gốc; file đặt GR-1..GR-7.
A39: • Chữ xanh = số liệu nhập; đen = công thức; ô nền vàng ở Scorecard = dropdown lựa chọn.

Sheet DECISION_MATRIX
A1: DECISION MATRIX — tất cả ma trận quyết định trong 1 sheet
A2: Hàng = lựa chọn A, cột = lựa chọn B, ô giao nhau = điểm/kết quả. Ô liên kết tự động tới sheet gốc (sửa số ở sheet M*/S* tương ứng).
A4: M1 · Hồ sơ (Màn 2) × Câu hỏi bổ sung (Màn 3) — giá trị thông tin tăng thêm (cùng khu vực = 1)
A5: Hàng ↓ / Cột → | C5: =M1_File_x_Q!C4 -> Traffic giảm, e-commerce tăng — khách rời bỏ hay đổi kê | D5: =M1_File_x_Q!D4 -> Chương trình vốn nào bị trì hoãn lâu nhất? | E5: =M1_File_x_Q!E4 -> Holiday kém 10% thì thanh khoản ra sao? | F5: =M1_File_x_Q!F4 -> Khoản nợ nào đến hạn sớm nhất? | G5: =M1_File_x_Q!G4 -> Nhóm sản phẩm nào đang hoạt động tốt nhất? | H5: =M1_File_x_Q!H4 -> Ban lãnh đạo có đồng thuận không? | I5: =M1_File_x_Q!I4 -> Có một điều khoản đặc biệt nào giữa Michael và nhà đầu
A6: ID | B6: Lựa chọn | C6: =M1_File_x_Q!C5 -> CH1-A | D6: =M1_File_x_Q!D5 -> CH1-B | E6: =M1_File_x_Q!E5 -> CH1-C | F6: =M1_File_x_Q!F5 -> CH1-D | G6: =M1_File_x_Q!G5 -> CH1-E | H6: =M1_File_x_Q!H5 -> CH1-F | I6: =M1_File_x_Q!I5 -> CH1-G
A7: =M1_File_x_Q!A6 -> HS-A | B7: =M1_File_x_Q!B6 -> Sales & Customer | C7: =M1_File_x_Q!C6 -> 1 | D7: =M1_File_x_Q!D6 -> 2 | E7: =M1_File_x_Q!E6 -> 4 | F7: =M1_File_x_Q!F6 -> 6 | G7: =M1_File_x_Q!G6 -> 2 | H7: =M1_File_x_Q!H6 -> 3 | I7: =M1_File_x_Q!I6 -> 3
A8: =M1_File_x_Q!A7 -> HS-B | B8: =M1_File_x_Q!B7 -> Stores & Investment | C8: =M1_File_x_Q!C7 -> 3 | D8: =M1_File_x_Q!D7 -> 1 | E8: =M1_File_x_Q!E7 -> 4 | F8: =M1_File_x_Q!F7 -> 6 | G8: =M1_File_x_Q!G7 -> 2 | H8: =M1_File_x_Q!H7 -> 3 | I8: =M1_File_x_Q!I7 -> 3
A9: =M1_File_x_Q!A8 -> HS-C | B9: =M1_File_x_Q!B8 -> Liquidity | C9: =M1_File_x_Q!C8 -> 3 | D9: =M1_File_x_Q!D8 -> 2 | E9: =M1_File_x_Q!E8 -> 1 | F9: =M1_File_x_Q!F8 -> 6 | G9: =M1_File_x_Q!G8 -> 2 | H9: =M1_File_x_Q!H8 -> 3 | I9: =M1_File_x_Q!I8 -> 3
A10: =M1_File_x_Q!A9 -> HS-D | B10: =M1_File_x_Q!B9 -> Capital Structure & Leverage History | C10: =M1_File_x_Q!C9 -> 3 | D10: =M1_File_x_Q!D9 -> 2 | E10: =M1_File_x_Q!E9 -> 4 | F10: =M1_File_x_Q!F9 -> 1 | G10: =M1_File_x_Q!G9 -> 2 | H10: =M1_File_x_Q!H9 -> 3 | I10: =M1_File_x_Q!I9 -> 3
A11: =M1_File_x_Q!A10 -> HS-E | B11: =M1_File_x_Q!B10 -> Product & Category Trends | C11: =M1_File_x_Q!C10 -> 3 | D11: =M1_File_x_Q!D10 -> 2 | E11: =M1_File_x_Q!E10 -> 4 | F11: =M1_File_x_Q!F10 -> 6 | G11: =M1_File_x_Q!G10 -> 1 | H11: =M1_File_x_Q!H10 -> 3 | I11: =M1_File_x_Q!I10 -> 3
A12: =M1_File_x_Q!A11 -> HS-F | B12: =M1_File_x_Q!B11 -> Management Track Record | C12: =M1_File_x_Q!C11 -> 3 | D12: =M1_File_x_Q!D11 -> 2 | E12: =M1_File_x_Q!E11 -> 4 | F12: =M1_File_x_Q!F11 -> 6 | G12: =M1_File_x_Q!G11 -> 2 | H12: =M1_File_x_Q!H11 -> 1 | I12: =M1_File_x_Q!I11 -> 3
A13: =M1_File_x_Q!A12 -> HS-G | B13: =M1_File_x_Q!B12 -> Governance & Family | C13: =M1_File_x_Q!C12 -> 3 | D13: =M1_File_x_Q!D12 -> 2 | E13: =M1_File_x_Q!E12 -> 4 | F13: =M1_File_x_Q!F12 -> 6 | G13: =M1_File_x_Q!G12 -> 2 | H13: =M1_File_x_Q!H12 -> 3 | I13: =M1_File_x_Q!I12 -> 1
A16: M2 · Hồ sơ (Màn 2) × Câu hỏi cuối (Màn 5) — điểm thông tin thêm
A17: Hàng ↓ / Cột → | C17: =M2_File_x_FQ!C4 -> Khoản nào khó cắt nhất? | D17: =M2_File_x_FQ!D4 -> Có thêm vốn thì dùng vào đâu? | E17: =M2_File_x_FQ!E4 -> Sao không đóng mạnh cửa hàng? | F17: =M2_File_x_FQ!F4 -> Amazon biến mất thì công ty khỏe chưa? | G17: =M2_File_x_FQ!G4 -> Nếu loại bỏ được phần lớn áp lực nợ, đã giải quyết toàn | H17: =M2_File_x_FQ!H4 -> Lo nhất điều gì trong 12 tháng tới? | I17: =M2_File_x_FQ!I4 -> Nếu EBITDA giảm thêm 5%, điều gì xảy ra ngay lập tức?
A18: ID | B18: Lựa chọn | C18: =M2_File_x_FQ!C5 -> CH2-A | D18: =M2_File_x_FQ!D5 -> CH2-B | E18: =M2_File_x_FQ!E5 -> CH2-C | F18: =M2_File_x_FQ!F5 -> CH2-D | G18: =M2_File_x_FQ!G5 -> CH2-E | H18: =M2_File_x_FQ!H5 -> CH2-F | I18: =M2_File_x_FQ!I5 -> CH2-G
A19: =M2_File_x_FQ!A6 -> HS-A | B19: =M2_File_x_FQ!B6 -> Sales & Customer | C19: =M2_File_x_FQ!C6 -> 0 | D19: =M2_File_x_FQ!D6 -> 2 | E19: =M2_File_x_FQ!E6 -> 2 | F19: =M2_File_x_FQ!F6 -> 5 | G19: =M2_File_x_FQ!G6 -> 2 | H19: =M2_File_x_FQ!H6 -> 0 | I19: =M2_File_x_FQ!I6 -> 0
A20: =M2_File_x_FQ!A7 -> HS-B | B20: =M2_File_x_FQ!B7 -> Stores & Investment | C20: =M2_File_x_FQ!C7 -> 0 | D20: =M2_File_x_FQ!D7 -> 5 | E20: =M2_File_x_FQ!E7 -> 5 | F20: =M2_File_x_FQ!F7 -> 0 | G20: =M2_File_x_FQ!G7 -> 3 | H20: =M2_File_x_FQ!H7 -> 0 | I20: =M2_File_x_FQ!I7 -> 0
A21: =M2_File_x_FQ!A8 -> HS-C | B21: =M2_File_x_FQ!B8 -> Liquidity | C21: =M2_File_x_FQ!C8 -> 0 | D21: =M2_File_x_FQ!D8 -> 2 | E21: =M2_File_x_FQ!E8 -> 0 | F21: =M2_File_x_FQ!F8 -> 0 | G21: =M2_File_x_FQ!G8 -> 0 | H21: =M2_File_x_FQ!H8 -> 5 | I21: =M2_File_x_FQ!I8 -> 3
A22: =M2_File_x_FQ!A9 -> HS-D | B22: =M2_File_x_FQ!B9 -> Capital Structure & Leverage History | C22: =M2_File_x_FQ!C9 -> 5 | D22: =M2_File_x_FQ!D9 -> 0 | E22: =M2_File_x_FQ!E9 -> 0 | F22: =M2_File_x_FQ!F9 -> 3 | G22: =M2_File_x_FQ!G9 -> 6 | H22: =M2_File_x_FQ!H9 -> 5 | I22: =M2_File_x_FQ!I9 -> 4
A23: =M2_File_x_FQ!A10 -> HS-E | B23: =M2_File_x_FQ!B10 -> Product & Category Trends | C23: =M2_File_x_FQ!C10 -> 0 | D23: =M2_File_x_FQ!D10 -> 0 | E23: =M2_File_x_FQ!E10 -> 0 | F23: =M2_File_x_FQ!F10 -> 3 | G23: =M2_File_x_FQ!G10 -> 0 | H23: =M2_File_x_FQ!H10 -> 0 | I23: =M2_File_x_FQ!I10 -> 0
A24: =M2_File_x_FQ!A11 -> HS-F | B24: =M2_File_x_FQ!B11 -> Management Track Record | C24: =M2_File_x_FQ!C11 -> 3 | D24: =M2_File_x_FQ!D11 -> 0 | E24: =M2_File_x_FQ!E11 -> 0 | F24: =M2_File_x_FQ!F11 -> 0 | G24: =M2_File_x_FQ!G11 -> 0 | H24: =M2_File_x_FQ!H11 -> 0 | I24: =M2_File_x_FQ!I11 -> 0
A25: =M2_File_x_FQ!A12 -> HS-G | B25: =M2_File_x_FQ!B12 -> Governance & Family | C25: =M2_File_x_FQ!C12 -> 2 | D25: =M2_File_x_FQ!D12 -> 4 | E25: =M2_File_x_FQ!E12 -> 4 | F25: =M2_File_x_FQ!F12 -> 3 | G25: =M2_File_x_FQ!G12 -> 5 | H25: =M2_File_x_FQ!H12 -> 4 | I25: =M2_File_x_FQ!I12 -> 10
A28: M3 · Chẩn đoán (Màn 6) × Hồ sơ (Màn 2) — bằng chứng ủng hộ
A29: Hàng ↓ / Cột → | C29: =M3_Dx_x_File!C4 -> Sales & Customer | D29: =M3_Dx_x_File!D4 -> Stores & Investment | E29: =M3_Dx_x_File!E4 -> Liquidity | F29: =M3_Dx_x_File!F4 -> Capital Structure & Leverage History | G29: =M3_Dx_x_File!G4 -> Product & Category Trends | H29: =M3_Dx_x_File!H4 -> Management Track Record | I29: =M3_Dx_x_File!I4 -> Governance & Family
A30: ID | B30: Lựa chọn | C30: =M3_Dx_x_File!C5 -> HS-A | D30: =M3_Dx_x_File!D5 -> HS-B | E30: =M3_Dx_x_File!E5 -> HS-C | F30: =M3_Dx_x_File!F5 -> HS-D | G30: =M3_Dx_x_File!G5 -> HS-E | H30: =M3_Dx_x_File!H5 -> HS-F | I30: =M3_Dx_x_File!I5 -> HS-G
A31: =M3_Dx_x_File!A6 -> CD-A | B31: =M3_Dx_x_File!B6 -> Áp lực Cạnh tranh (Competitive Pressure) | C31: =M3_Dx_x_File!C6 -> 25 | D31: =M3_Dx_x_File!D6 -> 4 | E31: =M3_Dx_x_File!E6 -> 0 | F31: =M3_Dx_x_File!F6 -> 2 | G31: =M3_Dx_x_File!G6 -> 8 | H31: =M3_Dx_x_File!H6 -> 6 | I31: =M3_Dx_x_File!I6 -> 0
A32: =M3_Dx_x_File!A7 -> CD-B | B32: =M3_Dx_x_File!B7 -> Nút thắt Vận hành (Operational Bottleneck) | C32: =M3_Dx_x_File!C7 -> 5 | D32: =M3_Dx_x_File!D7 -> 25 | E32: =M3_Dx_x_File!E7 -> 3 | F32: =M3_Dx_x_File!F7 -> 0 | G32: =M3_Dx_x_File!G7 -> 0 | H32: =M3_Dx_x_File!H7 -> 8 | I32: =M3_Dx_x_File!I7 -> 3
A33: =M3_Dx_x_File!A8 -> CD-C | B33: =M3_Dx_x_File!B8 -> Biểu hiện Thanh khoản tức thời (Liquidity Manifestation) | C33: =M3_Dx_x_File!C8 -> 0 | D33: =M3_Dx_x_File!D8 -> 4 | E33: =M3_Dx_x_File!E8 -> 25 | F33: =M3_Dx_x_File!F8 -> 10 | G33: =M3_Dx_x_File!G8 -> 0 | H33: =M3_Dx_x_File!H8 -> 3 | I33: =M3_Dx_x_File!I8 -> 0
A34: =M3_Dx_x_File!A9 -> CD-D | B34: =M3_Dx_x_File!B9 -> Nguyên nhân Cấu trúc (Structural Driver) | C34: =M3_Dx_x_File!C9 -> 2 | D34: =M3_Dx_x_File!D9 -> 0 | E34: =M3_Dx_x_File!E9 -> 10 | F34: =M3_Dx_x_File!F9 -> 25 | G34: =M3_Dx_x_File!G9 -> 0 | H34: =M3_Dx_x_File!H9 -> 8 | I34: =M3_Dx_x_File!I9 -> 6
A35: =M3_Dx_x_File!A10 -> CD-E | B35: =M3_Dx_x_File!B10 -> Áp lực Danh mục Sản phẩm (Category Pressure) | C35: =M3_Dx_x_File!C10 -> 6 | D35: =M3_Dx_x_File!D10 -> 0 | E35: =M3_Dx_x_File!E10 -> 0 | F35: =M3_Dx_x_File!F10 -> 0 | G35: =M3_Dx_x_File!G10 -> 25 | H35: =M3_Dx_x_File!H10 -> 3 | I35: =M3_Dx_x_File!I10 -> 2
A36: =M3_Dx_x_File!A11 -> CD-F | B36: =M3_Dx_x_File!B11 -> Chẩn đoán Đa yếu tố (Multi-Factor Diagnosis) | C36: =M3_Dx_x_File!C11 -> 6 | D36: =M3_Dx_x_File!D11 -> 6 | E36: =M3_Dx_x_File!E11 -> 6 | F36: =M3_Dx_x_File!F11 -> 15 | G36: =M3_Dx_x_File!G11 -> 6 | H36: =M3_Dx_x_File!H11 -> 8 | I36: =M3_Dx_x_File!I11 -> 10
A39: M4 · Chẩn đoán (Màn 6) × Phác đồ (Màn 7) — độ phù hợp 0–100
A40: Hàng ↓ / Cột → | C40: =M4_Dx_x_Tx!C4 -> Invest to Compete | D40: =M4_Dx_x_Tx!D4 -> Deep Cost Cutting | E40: =M4_Dx_x_Tx!E4 -> Debt Restructuring | F40: =M4_Dx_x_Tx!F4 -> Asset Sale | G40: =M4_Dx_x_Tx!G4 -> Bankruptcy Restructuring | H40: =M4_Dx_x_Tx!H4 -> Combined Restructuring
A41: ID | B41: Lựa chọn | C41: =M4_Dx_x_Tx!C5 -> PD-A | D41: =M4_Dx_x_Tx!D5 -> PD-B | E41: =M4_Dx_x_Tx!E5 -> PD-C | F41: =M4_Dx_x_Tx!F5 -> PD-D | G41: =M4_Dx_x_Tx!G5 -> PD-E | H41: =M4_Dx_x_Tx!H5 -> PD-F
A42: =M4_Dx_x_Tx!A6 -> CD-A | B42: =M4_Dx_x_Tx!B6 -> Áp lực Cạnh tranh (Competitive Pressure) | C42: =M4_Dx_x_Tx!C6 -> 90 | D42: =M4_Dx_x_Tx!D6 -> 35 | E42: =M4_Dx_x_Tx!E6 -> 30 | F42: =M4_Dx_x_Tx!F6 -> 25 | G42: =M4_Dx_x_Tx!G6 -> 20 | H42: =M4_Dx_x_Tx!H6 -> 60
A43: =M4_Dx_x_Tx!A7 -> CD-B | B43: =M4_Dx_x_Tx!B7 -> Nút thắt Vận hành (Operational Bottleneck) | C43: =M4_Dx_x_Tx!C7 -> 85 | D43: =M4_Dx_x_Tx!D7 -> 40 | E43: =M4_Dx_x_Tx!E7 -> 30 | F43: =M4_Dx_x_Tx!F7 -> 40 | G43: =M4_Dx_x_Tx!G7 -> 20 | H43: =M4_Dx_x_Tx!H7 -> 60
A44: =M4_Dx_x_Tx!A8 -> CD-C | B44: =M4_Dx_x_Tx!B8 -> Biểu hiện Thanh khoản tức thời (Liquidity Manifestation) | C44: =M4_Dx_x_Tx!C8 -> 30 | D44: =M4_Dx_x_Tx!D8 -> 65 | E44: =M4_Dx_x_Tx!E8 -> 80 | F44: =M4_Dx_x_Tx!F8 -> 85 | G44: =M4_Dx_x_Tx!G8 -> 50 | H44: =M4_Dx_x_Tx!H8 -> 65
A45: =M4_Dx_x_Tx!A9 -> CD-D | B45: =M4_Dx_x_Tx!B9 -> Nguyên nhân Cấu trúc (Structural Driver) | C45: =M4_Dx_x_Tx!C9 -> 20 | D45: =M4_Dx_x_Tx!D9 -> 40 | E45: =M4_Dx_x_Tx!E9 -> 85 | F45: =M4_Dx_x_Tx!F9 -> 55 | G45: =M4_Dx_x_Tx!G9 -> 80 | H45: =M4_Dx_x_Tx!H9 -> 90
A46: =M4_Dx_x_Tx!A10 -> CD-E | B46: =M4_Dx_x_Tx!B10 -> Áp lực Danh mục Sản phẩm (Category Pressure) | C46: =M4_Dx_x_Tx!C10 -> 55 | D46: =M4_Dx_x_Tx!D10 -> 35 | E46: =M4_Dx_x_Tx!E10 -> 30 | F46: =M4_Dx_x_Tx!F10 -> 20 | G46: =M4_Dx_x_Tx!G10 -> 25 | H46: =M4_Dx_x_Tx!H10 -> 50
A47: =M4_Dx_x_Tx!A11 -> CD-F | B47: =M4_Dx_x_Tx!B11 -> Chẩn đoán Đa yếu tố (Multi-Factor Diagnosis) | C47: =M4_Dx_x_Tx!C11 -> 45 | D47: =M4_Dx_x_Tx!D11 -> 40 | E47: =M4_Dx_x_Tx!E11 -> 65 | F47: =M4_Dx_x_Tx!F11 -> 55 | G47: =M4_Dx_x_Tx!G11 -> 70 | H47: =M4_Dx_x_Tx!H11 -> 90
...

Sheet Comparison
A1: MEDIFIN Case #01 — Score Comparison (Counselor Case Report)
A2: Kết quả song song của mọi lượt chơi trong Scorecard. Điểm /100 + kết cục 3 trục theo USER_FLOW gốc.
A4: Metric | B4: Weight / Max | C4: =Scorecard!C4 -> P1 · Ideal Path | D4: =Scorecard!D4 -> P2 · Debt-First (thiếu HS-G) | E4: =Scorecard!E4 -> P3 · Competitive Trap | F4: =Scorecard!F4 -> P4 · Cost-Cut + Chờ 6 tháng | G4: =Scorecard!G4 -> P5 · Sandbox (sửa thoải mái)
A5: Profile summary | C5: =Scorecard!C5 -> Nợ + Quản trị + Thanh khoản → CD-D → PD-F sau holiday | D5: =Scorecard!D5 -> Đúng gốc nợ, refinance thử, không mở HS-G | E5: =Scorecard!E5 -> Lặp khu vực đã mở → CD-A → đầu tư cạnh tranh, bỏ Governance | F5: =Scorecard!F5 -> CD-C → PD-B → TG-D; tái khám đổi chẩn đoán có dữ liệu mới | G5: =Scorecard!G5 -> CD-F → Phá sản → sau holiday; thử đổi bất kỳ ô nào
A6: Input status | C6: =Scorecard!C41 -> OK | D6: =Scorecard!D41 -> OK | E6: =Scorecard!E41 -> OK | F6: =Scorecard!F41 -> OK | G6: =Scorecard!G41 -> OK
A7: ★ OVERALL COUNSELOR SCORE /100 | B7: 100 | C7: =Scorecard!C146 -> 94.535714 | D7: =Scorecard!D146 -> 91.858811 | E7: =Scorecard!E146 -> 53.047863 | F7: =Scorecard!F146 -> 65.692623 | G7: =Scorecard!G146 -> 84.197336
A8: Xếp loại | C8: =Scorecard!C147 -> Excellent | D8: =Scorecard!D147 -> Excellent | E8: =Scorecard!E147 -> Developing | F8: =Scorecard!F147 -> Developing | G8: =Scorecard!G147 -> Proficient
A9: Xếp hạng (so với các cột khác) | C9: =RANK(C7,$C$7:$G$7) -> 1 | D9: =RANK(D7,$C$7:$G$7) -> 2 | E9: =RANK(E7,$C$7:$G$7) -> 5 | F9: =RANK(F7,$C$7:$G$7) -> 4 | G9: =RANK(G7,$C$7:$G$7) -> 3
A10: Uy tín cuối | C10: =Scorecard!C131 -> Cao | D10: =Scorecard!D131 -> Cao | E10: =Scorecard!E131 -> Trung bình | F10: =Scorecard!F131 -> Cao | G10: =Scorecard!G131 -> Cao
A11: Tier Tài chính | C11: =Scorecard!C135 -> Ổn định tài chính | D11: =Scorecard!D135 -> Ổn định mong manh | E11: =Scorecard!E135 -> Ổn định mong manh | F11: =Scorecard!F135 -> Ổn định mong manh | G11: =Scorecard!G135 -> Sụp đổ tài chính
A12: Tier Quản trị / Gia tộc | C12: =Scorecard!C142 -> Gia tộc đoàn kết | D12: =Scorecard!D142 -> Gia tộc chia rẽ, chưa vỡ | E12: =Scorecard!E142 -> Mất kiểm soát | F12: =Scorecard!F142 -> Mất kiểm soát | G12: =Scorecard!G142 -> Gia tộc chia rẽ, chưa vỡ
A13: ★ KẾT CỤC CUỐI | C13: =Scorecard!C143 -> "Người kế nghiệp" — David giữ ghế, công ty ổn định, gia đình miễn cưỡng hợp tác. | D13: =Scorecard!D143 -> "Chia phần trước khi chìm" — công ty nhỏ hơn hẳn; Michael/Richard rút được phần lớn giá trị; David bị ép nhượng bộ. | E13: =Scorecard!E143 -> "Tự ăn thịt mình" — công ty còn tồn tại về kỹ thuật nhưng gia đình tan đàn xẻ nghé, kiện tụng tiêu tốn vốn còn lại. | F13: =Scorecard!F143 -> "Tự ăn thịt mình" — công ty còn tồn tại về kỹ thuật nhưng gia đình tan đàn xẻ nghé, kiện tụng tiêu tốn vốn còn lại. | G13: =Scorecard!G143 -> "Quân cờ của quỹ" — Houndstooth hoặc chủ nợ tiếp quản; gia đình đấu đá đến phút cuối.
A14: ▶ Chi tiết 5 thành phần tạo nên Overall (bấm [+] để mở)
A15: Investigation /100 | B15: =Config!$B$41 -> 0.2 | C15: =Scorecard!C75 -> 100 | D15: =Scorecard!D75 -> 83.606557 | E15: =Scorecard!E75 -> 50.819672 | F15: =Scorecard!F75 -> 67.213115 | G15: =Scorecard!G75 -> 77.04918
A16: Diagnosis /100 | B16: =Config!$B$42 -> 0.25 | C16: =Scorecard!C79 -> 100 | D16: =Scorecard!D79 -> 100 | E16: =Scorecard!E79 -> 65 | F16: =Scorecard!F79 -> 77 | G16: =Scorecard!G79 -> 90
A17: Treatment /100 | B17: =Config!$B$43 -> 0.2 | C17: =Scorecard!C93 -> 90 | D17: =Scorecard!D93 -> 85 | E17: =Scorecard!E93 -> 48 | F17: =Scorecard!F93 -> 50 | G17: =Scorecard!G93 -> 76
A18: Execution Planning /100 | B18: =Config!$B$44 -> 0.2 | C18: =Scorecard!C99 -> 86.428571 | D18: =Scorecard!D99 -> 95 | E18: =Scorecard!E99 -> 70.357143 | F18: =Scorecard!F99 -> 62.5 | G18: =Scorecard!G99 -> 86.25
A19: Reassessment /100 | B19: =Config!$B$45 -> 0.15 | C19: =Scorecard!C128 -> 95 | D19: =Scorecard!D128 -> 94.25 | E19: =Scorecard!E128 -> 19.75 | F19: =Scorecard!F128 -> 70 | G19: =Scorecard!G128 -> 92.25
A20: Điểm thô Sức khỏe Tài chính (trước khi quy tier) | C20: =Scorecard!C134 -> 4 | D20: =Scorecard!D134 -> 2 | E20: =Scorecard!E134 -> 2 | F20: =Scorecard!F134 -> 1 | G20: =Scorecard!G134 -> 0
A21: Điểm thô Ổn định Quản trị (trước khi quy tier) | C21: =Scorecard!C141 -> 3 | D21: =Scorecard!D141 -> 2 | E21: =Scorecard!E141 -> -1 | F21: =Scorecard!F141 -> -1 | G21: =Scorecard!G141 -> 0
A22: ▶ Lựa chọn của người chơi ở từng màn (bấm [+] để mở)
A23: Hồ sơ đã xem (Màn 2) | C23: =Scorecard!C148 -> HS-D, HS-G, HS-C | D23: =Scorecard!D148 -> HS-D, HS-C, HS-A | E23: =Scorecard!E148 -> HS-A, HS-E, HS-B | F23: =Scorecard!F148 -> HS-C, HS-F, HS-B | G23: =Scorecard!G148 -> HS-D, HS-A, HS-E
A24: Câu hỏi CH1 / CH2 (Màn 3, 5) | C24: =Scorecard!C149 -> CH1-A, CH1-F | CH2-G | D24: =Scorecard!D149 -> CH1-G, CH1-F | CH2-E | E24: =Scorecard!E149 -> CH1-A, CH1-E | CH2-D | F24: =Scorecard!F149 -> CH1-D, CH1-G | CH2-F | G24: =Scorecard!G149 -> CH1-C, CH1-G | CH2-E
A25: Chẩn đoán đầu → sau tái khám (Màn 6, 11) | C25: =Scorecard!C150 -> CD-D | D25: =Scorecard!D150 -> CD-D | E25: =Scorecard!E150 -> CD-A | F25: =Scorecard!F150 -> CD-C → CD-D | G25: =Scorecard!G150 -> CD-F
A26: Phác đồ đầu → sau tái khám (Màn 7, 11) | C26: =Scorecard!C151 -> PD-F | D26: =Scorecard!D151 -> PD-C | E26: =Scorecard!E151 -> PD-A | F26: =Scorecard!F151 -> PD-B | G26: =Scorecard!G151 -> PD-E
A27: Thời điểm (Màn 8) | C27: =Scorecard!C52 -> TG-B | D27: =Scorecard!D52 -> TG-C | E27: =Scorecard!E52 -> TG-A | F27: =Scorecard!F52 -> TG-D | G27: =Scorecard!G52 -> TG-B
A28: Nhóm ưu tiên (Màn 9) | C28: =Scorecard!C152 -> GR-4, GR-7, GR-6 | D28: =Scorecard!D152 -> GR-4, GR-7, GR-6 | E28: =Scorecard!E152 -> GR-3, GR-6, GR-2 | F28: =Scorecard!F152 -> GR-2, GR-1, GR-5 | G28: =Scorecard!G152 -> GR-1, GR-4, GR-7
A29: ▶ FEEDBACK (Result → Reason → Meaning → Action → Limit) — bấm [+] để mở
A30: Investigation | C30: =Scorecard!C155 -> RESULT: 100/100 (High) → REASON: Bạn phủ được các khu vực then chốt (nợ 2015, thanh khoản, quản trị) và dùng câu hỏi bổ sung vào khu vực chưa mở. → MEANING: Chẩn đoán của bạn dựa trên dữ kiện thay vì suy đoán. → ACTION: Tiếp tục dùng câu hỏi để thu hẹp khoảng trống thông tin, không lặp lại khu vực đã có hồ sơ. → LIMIT: Chỉ được mở 3/7 hồ sơ nên luôn còn khu vực chưa thấy — đó là thiết kế. | D30: =Scorecard!D155 -> RESULT: 84/100 (High) → REASON: Bạn phủ được các khu vực then chốt (nợ 2015, thanh khoản, quản trị) và dùng câu hỏi bổ sung vào khu vực chưa mở. → MEANING: Chẩn đoán của bạn dựa trên dữ kiện thay vì suy đoán. → ACTION: Tiếp tục dùng câu hỏi để thu hẹp khoảng trống thông tin, không lặp lại khu vực đã có hồ sơ. → LIMIT: Chỉ được mở 3/7 hồ sơ nên luôn còn khu vực chưa thấy — đó là thiết kế. | E30: =Scorecard!E155 -> RESULT: 51/100 (Mid) → REASON: Bạn có một phần bằng chứng cốt lõi nhưng bỏ sót khu vực quan trọng hoặc lặp câu hỏi ở khu vực đã mở. → MEANING: Chẩn đoán có thể chỉ được ủng hộ một phần. → ACTION: Chọn hồ sơ bao phủ nợ/thanh khoản/quản trị; dùng 2 câu hỏi cho khu vực còn trống. → LIMIT: Điểm dựa trên thiết kế case; các đường điều tra khác vẫn có thể hợp lệ. | F30: =Scorecard!F155 -> RESULT: 67/100 (Mid) → REASON: Bạn có một phần bằng chứng cốt lõi nhưng bỏ sót khu vực quan trọng hoặc lặp câu hỏi ở khu vực đã mở. → MEANING: Chẩn đoán có thể chỉ được ủng hộ một phần. → ACTION: Chọn hồ sơ bao phủ nợ/thanh khoản/quản trị; dùng 2 câu hỏi cho khu vực còn trống. → LIMIT: Điểm dựa trên thiết kế case; các đường điều tra khác vẫn có thể hợp lệ. | G30: =Scorecard!G155 -> RESULT: 77/100 (Mid) → REASON: Bạn có một phần bằng chứng cốt lõi nhưng bỏ sót khu vực quan trọng hoặc lặp câu hỏi ở khu vực đã mở. → MEANING: Chẩn đoán có thể chỉ được ủng hộ một phần. → ACTION: Chọn hồ sơ bao phủ nợ/thanh khoản/quản trị; dùng 2 câu hỏi cho khu vực còn trống. → LIMIT: Điểm dựa trên thiết kế case; các đường điều tra khác vẫn có thể hợp lệ.
A31: Diagnosis | C31: =Scorecard!C157 -> RESULT: 100/100 (High) → REASON: Chẩn đoán của bạn chạm tới tầng cấu trúc sâu nhất (Nguyên nhân Cấu trúc / Đa yếu tố có đủ điều kiện) và có bằng chứng ủng hộ. → MEANING: Bạn phân biệt được nguyên nhân với triệu chứng, không dừng ở tầng bề mặt. → ACTION: Luôn hỏi: vấn đề này xảy ra trước hay là hệ quả? → LIMIT: 6 chẩn đoán là 6 TẦNG của cùng vấn đề, không phải đúng/sai; điểm cao hơn vì chạm tầng sâu, không vì 'đoán trúng đáp án'. | D31: =Scorecard!D157 -> RESULT: 100/100 (High) → REASON: Chẩn đoán của bạn chạm tới tầng cấu trúc sâu nhất (Nguyên nhân Cấu trúc / Đa yếu tố có đủ điều kiện) và có bằng chứng ủng hộ. → MEANING: Bạn phân biệt được nguyên nhân với triệu chứng, không dừng ở tầng bề mặt. → ACTION: Luôn hỏi: vấn đề này xảy ra trước hay là hệ quả? → LIMIT: 6 chẩn đoán là 6 TẦNG của cùng vấn đề, không phải đúng/sai; điểm cao hơn vì chạm tầng sâu, không vì 'đoán trúng đáp án'. | E31: =Scorecard!E157 -> RESULT: 65/100 (Mid) → REASON: Chẩn đoán chỉ ra một vấn đề có thật nhưng là hệ quả/triệu chứng hoặc thiếu bằng chứng. → MEANING: Phác đồ nhắm vào triệu chứng có thể không chữa được bệnh. → ACTION: Truy ngược về giao dịch 2015 và cấu trúc nợ. → LIMIT: CD-F cần HS-D và ≥1 hồ sơ liên quan, nếu không bị phạt Uy tín. | F31: =Scorecard!F157 -> RESULT: 77/100 (Mid) → REASON: Chẩn đoán chỉ ra một vấn đề có thật nhưng là hệ quả/triệu chứng hoặc thiếu bằng chứng. → MEANING: Phác đồ nhắm vào triệu chứng có thể không chữa được bệnh. → ACTION: Truy ngược về giao dịch 2015 và cấu trúc nợ. → LIMIT: CD-F cần HS-D và ≥1 hồ sơ liên quan, nếu không bị phạt Uy tín. | G31: =Scorecard!G157 -> RESULT: 90/100 (High) → REASON: Chẩn đoán của bạn chạm tới tầng cấu trúc sâu nhất (Nguyên nhân Cấu trúc / Đa yếu tố có đủ điều kiện) và có bằng chứng ủng hộ. → MEANING: Bạn phân biệt được nguyên nhân với triệu chứng, không dừng ở tầng bề mặt. → ACTION: Luôn hỏi: vấn đề này xảy ra trước hay là hệ quả? → LIMIT: 6 chẩn đoán là 6 TẦNG của cùng vấn đề, không phải đúng/sai; điểm cao hơn vì chạm tầng sâu, không vì 'đoán trúng đáp án'.
A32: Treatment | C32: =Scorecard!C159 -> RESULT: 90/100 (High) → REASON: Phác đồ (sau khi qua điều kiện Uy tín) khớp gốc rễ và chẩn đoán của bạn. → MEANING: Kế hoạch xử lý đúng chỗ thanh khoản/nợ bị kẹt. → ACTION: Thử xem thời điểm và nhóm ưu tiên thay đổi hậu quả thế nào. → LIMIT: Không phác đồ nào thắng mọi trục; hậu quả còn phụ thuộc thực thi. | D32: =Scorecard!D159 -> RESULT: 85/100 (High) → REASON: Phác đồ (sau khi qua điều kiện Uy tín) khớp gốc rễ và chẩn đoán của bạn. → MEANING: Kế hoạch xử lý đúng chỗ thanh khoản/nợ bị kẹt. → ACTION: Thử xem thời điểm và nhóm ưu tiên thay đổi hậu quả thế nào. → LIMIT: Không phác đồ nào thắng mọi trục; hậu quả còn phụ thuộc thực thi. | E32: =Scorecard!E159 -> RESULT: 48/100 (Low) → REASON: Phác đồ không khớp vấn đề thật. → MEANING: Có thể tiêu tốn cash/thời gian công ty không có. → ACTION: Đọc lại chẩn đoán và hỏi phác đồ nào tác động đúng nguyên nhân đó. → LIMIT: Độ khớp được chấm theo thiết kế case, không theo lý thuyết chung. | F32: =Scorecard!F159 -> RESULT: 50/100 (Mid) → REASON: Phác đồ giải quyết một phần vấn đề hoặc bị hạ cấp do thiếu Uy tín. → MEANING: Có thể mua thời gian nhưng chưa gỡ nguyên nhân. → ACTION: Cân nhắc phác đồ kết hợp nếu đủ Uy tín. → LIMIT: PD-A cần Uy tín ≥ TB, PD-F cần Uy tín Cao. | G32: =Scorecard!G159 -> RESULT: 76/100 (Mid) → REASON: Phác đồ giải quyết một phần vấn đề hoặc bị hạ cấp do thiếu Uy tín. → MEANING: Có thể mua thời gian nhưng chưa gỡ nguyên nhân. → ACTION: Cân nhắc phác đồ kết hợp nếu đủ Uy tín. → LIMIT: PD-A cần Uy tín ≥ TB, PD-F cần Uy tín Cao.
A33: Execution Planning | C33: =Scorecard!C161 -> RESULT: 86/100 (High) → REASON: Thời điểm và nhóm ưu tiên phù hợp với phác đồ. → MEANING: Kế hoạch vừa đúng vừa triển khai được. → ACTION: Tiếp tục nối phác đồ với đúng nhóm phải thuyết phục. → LIMIT: Phản ứng của Michael/chủ nợ thực tế có thể khó đoán hơn mô hình. | D33: =Scorecard!D161 -> RESULT: 95/100 (High) → REASON: Thời điểm và nhóm ưu tiên phù hợp với phác đồ. → MEANING: Kế hoạch vừa đúng vừa triển khai được. → ACTION: Tiếp tục nối phác đồ với đúng nhóm phải thuyết phục. → LIMIT: Phản ứng của Michael/chủ nợ thực tế có thể khó đoán hơn mô hình. | E33: =Scorecard!E161 -> RESULT: 70/100 (Mid) → REASON: Thời điểm hoặc nhóm ưu tiên chỉ hỗ trợ một phần phác đồ. → MEANING: Phác đồ tốt vẫn có thể yếu đi vì sai thứ tự. → ACTION: Tự hỏi ai phải đồng ý để phác đồ chạy, và khi nào. → LIMIT: Chỉ chọn 3/7 nhóm — đánh đổi là chủ đích. | F33: =Scorecard!F161 -> RESULT: 63/100 (Mid) → REASON: Thời điểm hoặc nhóm ưu tiên chỉ hỗ trợ một phần phác đồ. → MEANING: Phác đồ tốt vẫn có thể yếu đi vì sai thứ tự. → ACTION: Tự hỏi ai phải đồng ý để phác đồ chạy, và khi nào. → LIMIT: Chỉ chọn 3/7 nhóm — đánh đổi là chủ đích. | G33: =Scorecard!G161 -> RESULT: 86/100 (High) → REASON: Thời điểm và nhóm ưu tiên phù hợp với phác đồ. → MEANING: Kế hoạch vừa đúng vừa triển khai được. → ACTION: Tiếp tục nối phác đồ với đúng nhóm phải thuyết phục. → LIMIT: Phản ứng của Michael/chủ nợ thực tế có thể khó đoán hơn mô hình.
A34: Reassessment | C34: =Scorecard!C163 -> RESULT: 95/100 (High) → REASON: Bạn giữ hoặc đổi phán đoán đúng với dữ liệu mới từ Màn 10. → MEANING: Linh hoạt nghề nghiệp mà không phản ứng thái quá. → ACTION: Luôn kiểm tra dữ liệu mới xác nhận hay mâu thuẫn chẩn đoán. → LIMIT: Đổi có dữ liệu mới thì không mất Uy tín; đổi không có thì −1. | D34: =Scorecard!D163 -> RESULT: 94/100 (High) → REASON: Bạn giữ hoặc đổi phán đoán đúng với dữ liệu mới từ Màn 10. → MEANING: Linh hoạt nghề nghiệp mà không phản ứng thái quá. → ACTION: Luôn kiểm tra dữ liệu mới xác nhận hay mâu thuẫn chẩn đoán. → LIMIT: Đổi có dữ liệu mới thì không mất Uy tín; đổi không có thì −1. | E34: =Scorecard!E163 -> RESULT: 20/100 (Low) → REASON: Tái khám không khớp dữ liệu mới hoặc bị trừ Uy tín vì đổi thiếu căn cứ. → MEANING: Bỏ qua hoặc phản ứng thái quá làm giảm độ tin cậy. → ACTION: Quyết định chẩn đoán sai hay chỉ phác đồ sai trước khi đổi. → LIMIT: Có thể chơi lại để thử đường tái khám khác. | F34: =Scorecard!F163 -> RESULT: 70/100 (Mid) → REASON: Tái khám chỉ khớp một phần với dữ liệu mới. → MEANING: Có thể giữ phán đoán yếu hoặc đổi phán đoán tốt. → ACTION: Hỏi: sự kiện nào ở Màn 10 thật sự mâu thuẫn chẩn đoán? → LIMIT: Một số đổi là phán đoán chủ quan; điểm từng phần là chủ đích. | G34: =Scorecard!G163 -> RESULT: 92/100 (High) → REASON: Bạn giữ hoặc đổi phán đoán đúng với dữ liệu mới từ Màn 10. → MEANING: Linh hoạt nghề nghiệp mà không phản ứng thái quá. → ACTION: Luôn kiểm tra dữ liệu mới xác nhận hay mâu thuẫn chẩn đoán. → LIMIT: Đổi có dữ liệu mới thì không mất Uy tín; đổi không có thì −1.

Sheet Scorecard
A1: Scorecard — nhập lựa chọn của người chơi, đọc toàn bộ điểm
A2: Mỗi cột = một người chơi / lượt chơi. Đổi các dropdown vàng; mọi mục bên dưới tự tính lại. P1–P4 là lượt chơi mẫu để so sánh.
A4: Item | B4: Rule / source | C4: P1 · Ideal Path | D4: P2 · Debt-First (thiếu HS-G) | E4: P3 · Competitive Trap | F4: P4 · Cost-Cut + Chờ 6 tháng | G4: P5 · Sandbox (sửa thoải mái)
A5: Profile summary | C5: Nợ + Quản trị + Thanh khoản → CD-D → PD-F sau holiday | D5: Đúng gốc nợ, refinance thử, không mở HS-G | E5: Lặp khu vực đã mở → CD-A → đầu tư cạnh tranh, bỏ Governance | F5: CD-C → PD-B → TG-D; tái khám đổi chẩn đoán có dữ liệu mới | G5: CD-F → Phá sản → sau holiday; thử đổi bất kỳ ô nào
A6: A. PLAYER INPUTS (dropdowns)
A7: Màn 2 · Hồ sơ 1 | B7: S2_Files | C7: HS-D - Capital Structure & Leverage History | D7: HS-D - Capital Structure & Leverage History | E7: HS-A - Sales & Customer | F7: HS-C - Liquidity | G7: HS-D - Capital Structure & Leverage History
A8: Màn 2 · Hồ sơ 2 | B8: S2_Files | C8: HS-G - Governance & Family | D8: HS-C - Liquidity | E8: HS-E - Product & Category Trends | F8: HS-F - Management Track Record | G8: HS-A - Sales & Customer
A9: Màn 2 · Hồ sơ 3 | B9: S2_Files | C9: HS-C - Liquidity | D9: HS-A - Sales & Customer | E9: HS-B - Stores & Investment | F9: HS-B - Stores & Investment | G9: HS-E - Product & Category Trends
A10: Màn 3 · Câu hỏi bổ sung 1 | B10: S3_Questions | C10: CH1-A - Traffic giảm, e-commerce tăng — khách rời bỏ hay đổi kênh? | D10: CH1-G - Có một điều khoản đặc biệt nào giữa Michael và nhà đầu tư bên ngoài không? | E10: CH1-A - Traffic giảm, e-commerce tăng — khách rời bỏ hay đổi kênh? | F10: CH1-D - Khoản nợ nào đến hạn sớm nhất? | G10: CH1-C - Holiday kém 10% thì thanh khoản ra sao?
A11: Màn 3 · Câu hỏi bổ sung 2 | B11: S3_Questions | C11: CH1-F - Ban lãnh đạo có đồng thuận không? | D11: CH1-F - Ban lãnh đạo có đồng thuận không? | E11: CH1-E - Nhóm sản phẩm nào đang hoạt động tốt nhất? | F11: CH1-G - Có một điều khoản đặc biệt nào giữa Michael và nhà đầu tư bên ngoài không? | G11: CH1-G - Có một điều khoản đặc biệt nào giữa Michael và nhà đầu tư bên ngoài không?
A12: Màn 5 · Câu hỏi cuối | B12: S5_FinalQ | C12: CH2-G - Nếu EBITDA giảm thêm 5%, điều gì xảy ra ngay lập tức? | D12: CH2-E - Nếu loại bỏ được phần lớn áp lực nợ, đã giải quyết toàn bộ vấn đề chưa? | E12: CH2-D - Amazon biến mất thì công ty khỏe chưa? | F12: CH2-F - Lo nhất điều gì trong 12 tháng tới? | G12: CH2-E - Nếu loại bỏ được phần lớn áp lực nợ, đã giải quyết toàn bộ vấn đề chưa?
A13: Màn 6 · Chẩn đoán | B13: S6_Diagnosis | C13: CD-D - Nguyên nhân Cấu trúc (Structural Driver) | D13: CD-D - Nguyên nhân Cấu trúc (Structural Driver) | E13: CD-A - Áp lực Cạnh tranh (Competitive Pressure) | F13: CD-C - Biểu hiện Thanh khoản tức thời (Liquidity Manifestation) | G13: CD-F - Chẩn đoán Đa yếu tố (Multi-Factor Diagnosis)
A14: Màn 7 · Phác đồ | B14: S7_Treatment | C14: PD-F - Combined Restructuring | D14: PD-C - Debt Restructuring | E14: PD-A - Invest to Compete | F14: PD-B - Deep Cost Cutting | G14: PD-E - Bankruptcy Restructuring
A15: Màn 8 · Thời điểm | B15: S8_Timing | C15: TG-B - Sau holiday season | D15: TG-C - Thử tái cấp vốn trước khi cam kết kế hoạch | E15: TG-A - Thực hiện ngay | F15: TG-D - Chờ 6 tháng | G15: TG-B - Sau holiday season
A16: Màn 9 · Nhóm ưu tiên 1 | B16: S9_Stakeholders | C16: GR-4 - Creditors | D16: GR-4 - Creditors | E16: GR-3 - Customers | F16: GR-2 - Employees | G16: GR-1 - Suppliers
A17: Màn 9 · Nhóm ưu tiên 2 | B17: S9_Stakeholders | C17: GR-7 - Governance & Family | D17: GR-7 - Governance & Family | E17: GR-6 - Holiday Inventory | F17: GR-1 - Suppliers | G17: GR-4 - Creditors
A18: Màn 9 · Nhóm ưu tiên 3 | B18: S9_Stakeholders | C18: GR-6 - Holiday Inventory | D18: GR-6 - Holiday Inventory | E18: GR-2 - Employees | F18: GR-5 - Landlords | G18: GR-7 - Governance & Family
A19: Màn 11 · Quyết định tái khám | B19: S11_Reassess | C19: Keep | D19: Keep | E19: Keep | F19: Revise Diagnosis | G19: Keep
A20: Màn 11 · Chẩn đoán mới (nếu đổi) | B20: S6_Diagnosis | F20: CD-D - Nguyên nhân Cấu trúc (Structural Driver)
A21: Màn 11 · Phác đồ mới (nếu đổi) | B21: S7_Treatment
A22: TÓM TẮT KẾT QUẢ — chỉ cần đọc phần này (chi tiết công thức gấp lại bên dưới)
A23: Trạng thái nhập liệu | C23: =C41 -> OK | D23: =D41 -> OK | E23: =E41 -> OK | F23: =F41 -> OK | G23: =G41 -> OK
A24: Màn 2 · Điểm Hồ sơ đã chọn (đơn vị thô, không phải /100) | B24: tra S2_Files | C24: =C71 -> 40 | D24: =D71 -> 33 | E24: =E71 -> 19 | F24: =F71 -> 23 | G24: =G71 -> 28
A25: Màn 3 · Điểm Câu hỏi bổ sung (đơn vị thô) | B25: tra M1 | C25: =C72+C73 -> 6 | D25: =D72+D73 -> 6 | E25: =E72+E73 -> 2 | F25: =F72+F73 -> 9 | G25: =G72+G73 -> 7
A26: Màn 5 · Điểm Câu hỏi cuối (đơn vị thô) | B26: tra S5+M2 | C26: =C74 -> 15 | D26: =D74 -> 12 | E26: =E74 -> 10 | F26: =F74 -> 9 | G26: =G74 -> 12
A27: → Investigation QUY VỀ /100 (3 dòng trên gộp lại, chia cho mức tối đa có thể đạt) | C27: =C75 -> 100 | D27: =D75 -> 83.606557 | E27: =E75 -> 50.819672 | F27: =F75 -> 67.213115 | G27: =G75 -> 77.04918
A28: Màn 6 · Diagnosis /100 | B28: primary+evidence, tự nhiên ra /100 | C28: =C79 -> 100 | D28: =D79 -> 100 | E28: =E79 -> 65 | F28: =F79 -> 77 | G28: =G79 -> 90
A29: Màn 7 · Treatment /100 | B29: tra M4 (đã là thang 0–100 sẵn) | C29: =C93 -> 90 | D29: =D93 -> 85 | E29: =E93 -> 48 | F29: =F93 -> 50 | G29: =G93 -> 76
A30: Màn 8–9 · Execution /100 | B30: M5 và M6 đều quy về /100 trước khi gộp | C30: =C99 -> 86.428571 | D30: =D99 -> 95 | E30: =E99 -> 70.357143 | F30: =F99 -> 62.5 | G30: =G99 -> 86.25
A31: Màn 11 · Reassessment /100 | C31: =C128 -> 95 | D31: =D128 -> 94.25 | E31: =E128 -> 19.75 | F31: =F128 -> 70 | G31: =G128 -> 92.25
A32: ★ TỔNG ĐIỂM COUNSELOR /100 (=20%×Inv +25%×Dia +20%×Tre +20%×Exe +15%×Rea — 5 số trên CỘNG CÓ TRỌNG SỐ, KHÔNG cộng điểm thô ở M2/M3/M5) | B32: Config | C32: =C146 -> 94.535714 | D32: =D146 -> 91.858811 | E32: =E146 -> 53.047863 | F32: =F146 -> 65.692623 | G32: =G146 -> 84.197336
A33: Xếp loại | C33: =C147 -> Excellent | D33: =D147 -> Excellent | E33: =E147 -> Developing | F33: =F147 -> Developing | G33: =G147 -> Proficient
A34: ─── 3 trục kết cục (điểm THÔ riêng, KHÔNG liên quan tới /100 ở trên) ───
A35: Uy tín cuối | C35: =C131 -> Cao | D35: =D131 -> Cao | E35: =E131 -> Trung bình | F35: =F131 -> Cao | G35: =G131 -> Cao
A36: Sức khỏe Tài chính (điểm thô + tier) | C36: =TEXT(C134,"0")&" → "&C135 -> 4 → Ổn định tài chính | D36: =TEXT(D134,"0")&" → "&D135 -> 2 → Ổn định mong manh | E36: =TEXT(E134,"0")&" → "&E135 -> 2 → Ổn định mong manh | F36: =TEXT(F134,"0")&" → "&F135 -> 1 → Ổn định mong manh | G36: =TEXT(G134,"0")&" → "&G135 -> 0 → Sụp đổ tài chính
A37: Ổn định Quản trị (điểm thô + tier) | C37: =TEXT(C141,"0")&" → "&C142 -> 3 → Gia tộc đoàn kết | D37: =TEXT(D141,"0")&" → "&D142 -> 2 → Gia tộc chia rẽ, chưa vỡ | E37: =TEXT(E141,"0")&" → "&E142 -> -1 → Mất kiểm soát | F37: =TEXT(F141,"0")&" → "&F142 -> -1 → Mất kiểm soát | G37: =TEXT(G141,"0")&" → "&G142 -> 0 → Gia tộc chia rẽ, chưa vỡ
A38: ★ KẾT CỤC CUỐI CÙNG | B38: tra ma trận 3×3 Endings | C38: =C143 -> "Người kế nghiệp" — David giữ ghế, công ty ổn định, gia đình miễn cưỡng hợp tác. | D38: =D143 -> "Chia phần trước khi chìm" — công ty nhỏ hơn hẳn; Michael/Richard rút được phần lớn giá trị; David bị ép nhượng bộ. | E38: =E143 -> "Tự ăn thịt mình" — công ty còn tồn tại về kỹ thuật nhưng gia đình tan đàn xẻ nghé, kiện tụng tiêu tốn vốn còn lại. | F38: =F143 -> "Tự ăn thịt mình" — công ty còn tồn tại về kỹ thuật nhưng gia đình tan đàn xẻ nghé, kiện tụng tiêu tốn vốn còn lại. | G38: =G143 -> "Quân cờ của quỹ" — Houndstooth hoặc chủ nợ tiếp quản; gia đình đấu đá đến phút cuối.
A39: ▶ CHI TIẾT CÔNG THỨC BÊN DƯỚI (bấm nút [+] ở lề trái để mở — chỉ cần khi muốn kiểm tra lại cách tính)
A40: B. VALIDATION (thông báo lỗi & cảnh báo)
A41: Input status | B41: OK = flow tiếp tục được | C41: =IF(OR(COUNTA(C7:C9)<>3,C7=C8,C7=C9,C8=C9),"Select exactly 3 Diagnostic Files to continue.",IF(OR(COUNTA(C10:C11)<>2,C10=C11),"Select exactly 2 Follow-Up Questions to continue.",IF(C12="","Select one final question before continuing.",IF(C13="","Select a Primary Diagnosis before submitting your diagnosis.",IF(C14="","Select a treatment strategy to continue.",IF(C15="","Select an implementation timing.",IF(OR(COUNTA(C16:C18)<>3,C16=C17,C16=C18,C17=C18),"Select exactly 3 stakeholder priorities.",IF(OR(C19="",AND(OR(C19="Revise Diagnosis",C19="Revise Both"),C20=""),AND(OR(C19="Revise Treatment",C19="Revise Both"),C21="")),"Complete your revised decision before closing the case.","OK")))))))) -> OK | D41: =IF(OR(COUNTA(D7:D9)<>3,D7=D8,D7=D9,D8=D9),"Select exactly 3 Diagnostic Files to continue.",IF(OR(COUNTA(D10:D11)<>2,D10=D11),"Select exactly 2 Follow-Up Questions to continue.",IF(D12="","Select one final question before continuing.",IF(D13="","Select a Primary Diagnosis before submitting your diagnosis.",IF(D14="","Select a treatment strategy to continue.",IF(D15="","Select an implementation timing.",IF(OR(COUNTA(D16:D18)<>3,D16=D17,D16=D18,D17=D18),"Select exactly 3 stakeholder priorities.",IF(OR(D19="",AND(OR(D19="Revise Diagnosis",D19="Revise Both"),D20=""),AND(OR(D19="Revise Treatment",D19="Revise Both"),D21="")),"Complete your revised decision before closing the case.","OK")))))))) -> OK | E41: =IF(OR(COUNTA(E7:E9)<>3,E7=E8,E7=E9,E8=E9),"Select exactly 3 Diagnostic Files to continue.",IF(OR(COUNTA(E10:E11)<>2,E10=E11),"Select exactly 2 Follow-Up Questions to continue.",IF(E12="","Select one final question before continuing.",IF(E13="","Select a Primary Diagnosis before submitting your diagnosis.",IF(E14="","Select a treatment strategy to continue.",IF(E15="","Select an implementation timing.",IF(OR(COUNTA(E16:E18)<>3,E16=E17,E16=E18,E17=E18),"Select exactly 3 stakeholder priorities.",IF(OR(E19="",AND(OR(E19="Revise Diagnosis",E19="Revise Both"),E20=""),AND(OR(E19="Revise Treatment",E19="Revise Both"),E21="")),"Complete your revised decision before closing the case.","OK")))))))) -> OK | F41: =IF(OR(COUNTA(F7:F9)<>3,F7=F8,F7=F9,F8=F9),"Select exactly 3 Diagnostic Files to continue.",IF(OR(COUNTA(F10:F11)<>2,F10=F11),"Select exactly 2 Follow-Up Questions to continue.",IF(F12="","Select one final question before continuing.",IF(F13="","Select a Primary Diagnosis before submitting your diagnosis.",IF(F14="","Select a treatment strategy to continue.",IF(F15="","Select an implementation timing.",IF(OR(COUNTA(F16:F18)<>3,F16=F17,F16=F18,F17=F18),"Select exactly 3 stakeholder priorities.",IF(OR(F19="",AND(OR(F19="Revise Diagnosis",F19="Revise Both"),F20=""),AND(OR(F19="Revise Treatment",F19="Revise Both"),F21="")),"Complete your revised decision before closing the case.","OK")))))))) -> OK | G41: =IF(OR(COUNTA(G7:G9)<>3,G7=G8,G7=G9,G8=G9),"Select exactly 3 Diagnostic Files to continue.",IF(OR(COUNTA(G10:G11)<>2,G10=G11),"Select exactly 2 Follow-Up Questions to continue.",IF(G12="","Select one final question before continuing.",IF(G13="","Select a Primary Diagnosis before submitting your diagnosis.",IF(G14="","Select a treatment strategy to continue.",IF(G15="","Select an implementation timing.",IF(OR(COUNTA(G16:G18)<>3,G16=G17,G16=G18,G17=G18),"Select exactly 3 stakeholder priorities.",IF(OR(G19="",AND(OR(G19="Revise Diagnosis",G19="Revise Both"),G20=""),AND(OR(G19="Revise Treatment",G19="Revise Both"),G21="")),"Complete your revised decision before closing the case.","OK")))))))) -> OK
...

Sheet Case_Facts
A1: Case #01 — Toy Kingdom Inc. (mô phỏng Toys "R" Us): tổng quan & bí mật nền
A2: Nội dung lấy từ USER_FLOW_GỐC. Mục 'GIẢ ĐỊNH THIẾT KẾ' là phần bổ sung để chấm điểm.
A4: Nhóm | B4: Trường | C4: Nội dung
A5: Tổng quan | B5: Công ty | C5: Toy Kingdom Inc. (mô phỏng Toys "R" Us, Inc.)
A6: Tổng quan | B6: Ngành / quy mô | C6: Specialty retail — đồ chơi & sản phẩm trẻ em; ~1.700 cửa hàng toàn cầu.
A7: Tổng quan | B7: Doanh thu FY2026 | C7: $11.540 tỷ
A8: Tổng quan | B8: Sở hữu | C8: Gia đình Anderson 78% (David — CEO, Michael — em trai, Richard — chú); quỹ đầu tư tư nhân 22%.
A9: Tổng quan | B9: Kết quả FY2026 | C9: Adjusted EBITDA $792m; Operating Earnings $460m; Net Loss attributable −$36m.
A10: Tổng quan | B10: Lý do khám | C10: Kinh doanh có dấu hiệu cải thiện nhưng thiếu nguồn lực tái đầu tư, áp lực tài chính tăng, ban lãnh đạo gia đình chia rẽ.
A11: Màn 1 | B11: David (CEO) | C11: "Sales tiếp tục giảm… Một số chỉ số tốt lên nhưng công ty vẫn ngày càng khó xoay xở." Không biết vấn đề nằm ở thị trường, cấu trúc tài chính hay ban lãnh đạo.
A12: Bí mật nền | B12: Thỏa thuận Michael–Houndstooth | C12: Nếu Adjusted EBITDA giảm thêm 5% so với FY2026, Houndstooth có quyền mua ưu tiên cổ phần gia đình với giá thấp. Chỉ xác nhận đầy đủ khi mở HS-G.
A13: Bí mật nền | B13: Richard | C13: Muốn thanh lý tài sản quốc tế để chia tiền mặt ngay.
A14: Trục theo dõi | B14: Uy tín | C14: Thấp / Trung bình / Cao — không đổi ô kết cục, đổi cách mô tả người chơi; là điều kiện mở PD-A (≥ TB) và PD-F (Cao).
A15: Trục theo dõi | B15: Sức khỏe Tài chính | C15: Điểm → Ổn định / Mong manh / Sụp đổ.
... A20: GIẢ ĐỊNH THIẾT KẾ | B20: Lớp điểm /100 | C20: Investigation, Diagnosis, Treatment, Execution, Reassessment và Overall là lớp chấm điểm bổ sung để so sánh; kết cục cuối vẫn theo 3 trục của USER_FLOW gốc.

Sheet Financials
A1: Màn 4 — Báo cáo tài chính đầy đủ (triệu USD)
A2: Số liệu từ USER_FLOW gốc (xanh = dữ liệu; đen = công thức). Chỉ số đòn bẩy là phần tính thêm.
A4: Chỉ tiêu | B4: FY2024 | C4: FY2025 | D4: FY2026 | E4: FY26 vs FY25 | F4: Tín hiệu
A5: CONSOLIDATED INCOME STATEMENT
A6: Net Sales | B6: 12361 | C6: 11802 | D6: 11540 | E6: =D6-C6 -> -262 | F6: Doanh thu giảm 2.2%
A7: Cost of Sales | B7: 7931 | C7: 7576 | D7: 7432 | E7: =D7-C7 -> -144
A8: Gross Margin | B8: =B6-B7 -> 4430 | C8: =C6-C7 -> 4226 | D8: =D6-D7 -> 4108 | E8: =D8-C8 -> -118
A9: SG&A | B9: 3915 | C9: 3593 | D9: 3480 | E9: =D9-C9 -> -113
A10: Depreciation & Amortization | B10: 377 | C10: 343 | D10: 317 | E10: =D10-C10 -> -26
A11: Other Income, net | B11: 53 | C11: 88 | D11: 149 | E11: =D11-C11 -> 61 | F11: Tăng bất thường (bảo hiểm nhân thọ, tranh chấp)
A12: Operating Earnings | B12: =B8-B9-B10+B11 -> 191 | C12: =C8-C9-C10+C11 -> 378 | D12: =D8-D9-D10+D11 -> 460 | E12: =D12-C12 -> 82
A13: Interest Expense | B13: 451 | C13: 429 | D13: 457 | E13: =D13-C13 -> 28 | F13: Lãi vay ≈ Operating Earnings
A14: Interest Income | B14: 4 | C14: 3 | D14: 2 | E14: =D14-C14 -> -1
A15: Earnings / (Loss) Before Tax | B15: =B12-B13+B14 -> -256 | C15: =C12-C13+C14 -> -48 | D15: =D12-D13+D14 -> 5 | E15: =D15-C15 -> 53
A16: Income Tax Expense | B16: 32 | C16: 76 | D16: 34 | E16: =D16-C16 -> -42
A17: Net Loss | B17: =B15-B16 -> -288 | C17: =C15-C16 -> -124 | D17: =D15-D16 -> -29 | E17: =D17-C17 -> 95
A18: Noncontrolling Interest | B18: 4 | C18: 6 | D18: 7 | E18: =D18-C18 -> 1
A19: Net Loss attributable to Toys "R" Us | B19: =B17-B18 -> -292 | C19: =C17-C18 -> -130 | D19: =D17-D18 -> -36 | E19: =D19-C19 -> 94 | F19: Lỗ thu hẹp nhưng vẫn lỗ
A20: OPERATING METRICS
A21: Adjusted EBITDA | B21: 642 | C21: 800 | D21: 792 | E21: =D21-C21 -> -8 | F21: Giảm 1.0% — đã dùng 1/5 biên trigger Houndstooth
A22: Consolidated SSS | B22: 0 | C22: 0.009 | D22: -0.014
A23: Gross Margin % | B23: =B8/B6 -> 0.35838524 | C23: =C8/C6 -> 0.3580749 | D23: =D8/D6 -> 0.3559792
A24: SG&A / Sales | B24: =B9/B6 -> 0.31672195 | C24: =C9/C6 -> 0.30443993 | D24: =D9/D6 -> 0.30155979
A25: Net Sales growth | C25: =C6/B6-1 -> -0.045222878 | D25: =D6/C6-1 -> -0.022199627
A26: BALANCE SHEET SNAPSHOT — FY2026
A27: Cash & Cash Equivalents | D27: 566
A28: Receivables | D28: 255
A29: Inventory | D29: 2476
A30: Total Current Assets | D30: 3389
A31: Property & Equipment | D31: 3067
A32: Total Indebtedness | D32: 4800 | F32: ~$4.8bn
A33: Secured Indebtedness | D33: 3400 | F33: ~$3.4bn
A34: Stockholders' Equity (deficit) | D34: -1300 | F34: ~$1.3bn deficit
A35: LEVERAGE INDICATORS — FY2026 (tính thêm)
A36: Debt / Adj. EBITDA (x) | D36: =D32/D21 -> 6.0606061 | F36: Đòn bẩy rất cao
A37: Secured debt / Adj. EBITDA (x) | D37: =D33/D21 -> 4.2929293
A38: Net debt / Adj. EBITDA (x) | D38: =(D32-D27)/D21 -> 5.3459596
A39: Adj. EBITDA / Interest expense (x) | D39: =D21/D13 -> 1.7330416 | F39: Bao phủ lãi mỏng
A40: Operating Earnings / Interest (x) | D40: =D12/D13 -> 1.0065646 | F40: ≈ 1.0x
A41: Cash / Total debt | D41: =D27/D32 -> 0.11791667
...

Sheet Config
A1: Config — tham số toàn cục (chữ xanh = chỉnh được)
A2: Đổi giá trị ở đây, mọi điểm ở Scorecard / Comparison tự tính lại.
A3: Parameter | B3: Value | C3: Note
A4: Chẩn đoán ở TẦNG CẤU TRÚC sâu nhất, dùng làm mốc chấm Treatment (ID) | B4: CD-D | C4: HS-D ghi 'Gốc rễ: giao dịch 2015'. Đây là mốc CHẤM ĐIỂM, không phải tuyên bố '6 chẩn đoán kia sai' (USER_FLOW bản sửa, Màn 6).
A5: Điểm câu hỏi bổ sung khi khu vực ĐÃ mở hồ sơ | B5: 1 | C5: USER_FLOW: chỉ củng cố thêm chi tiết nhỏ.
A6: Trần điểm câu hỏi cuối | B6: 15
A7: Điểm thông tin tối đa đạt được (chuẩn hóa Investigation) | B7: 61 | C7: Tính bằng vét cạn: 3 hồ sơ + 2 CH1 + 1 CH2 tốt nhất. Tính lại nếu đổi điểm.
A8: Trần Evidence support (Diagnosis) | B8: 40
A9: Hệ số bằng chứng từ câu hỏi CH1 (so với hồ sơ đầy đủ) | B9: 0.5
A10: Hệ số điểm CD-F khi THIẾU điều kiện | B10: 0.5 | C10: Kèm Uy tín −1 (USER_FLOW Màn 6).
A11: Uy tín khởi điểm (điểm) | B11: 2 | C11: GIẢ ĐỊNH: case gốc không nêu điểm khởi đầu. 2 = Trung bình.
A12: Uy tín: Trung bình khi ≥ | B12: 2 | C12: Thấp: <2 · Trung bình: 2–3 · Cao: ≥4.
A13: Uy tín: Cao khi ≥ | B13: 4 | C13: PD-F cần Cao; PD-A cần ≥ Trung bình.
A14: Uy tín: chẩn đoán CÓ căn cứ | B14: 1 | C14: GIẢ ĐỊNH (case gốc: 'tăng/giảm theo lựa chọn có/không đủ căn cứ').
A15: Uy tín: chẩn đoán KHÔNG có căn cứ | B15: -1 | C15: Căn cứ = đã mở HS-x hoặc hỏi CH1-x của chính chẩn đoán (CD-F: đủ điều kiện).
A16: Uy tín: điều tra hiệu quả (2 CH1 vào 2 khu vực chưa mở) | B16: 1 | C16: GIẢ ĐỊNH — thưởng cho việc không lãng phí 'cơ hội duy nhất'.
A17: Uy tín: chọn CD-F thiếu điều kiện | B17: -1 | C17: Theo USER_FLOW Màn 6.
A18: Uy tín: TG-C refinance thử thất bại | B18: -1 | C18: Theo USER_FLOW Màn 8. Thất bại = KHÔNG ưu tiên Creditors (GIẢ ĐỊNH).
A19: Uy tín: mỗi lần đổi chẩn đoán/phác đồ thiếu dữ liệu mới | B19: -1 | C19: Theo USER_FLOW Màn 11.
A20: Treatment: trọng số độ phù hợp với nguyên nhân gốc | B20: 0.6
A21: Treatment: trọng số độ phù hợp với chẩn đoán của người chơi | B21: 0.4
A22: Execution: trọng số thời điểm | B22: 0.5
A23: Execution: trọng số nhóm ưu tiên | B23: 0.5
A24: Độ phù hợp để tính là kế hoạch MẠNH (Reassessment) | B24: 80
A25: Reassessment: trọng số quyết định | B25: 0.7
A26: Reassessment: trọng số chất lượng phán đoán cuối | B26: 0.3
A27: Reassessment: phạt (điểm /100) mỗi lần đổi thiếu căn cứ | B27: 10
A28: Tài chính: Ổn định khi điểm ≥ | B28: 4 | C28: Đã CHỐT CHÍNH THỨC theo USER_FLOW bản sửa (Màn 12): ngưỡng ≥5 gốc không đạt được với thang điểm (tối đa +4) nên đội quyết định đổi thành ≥4 — không còn là giả định.
A29: Tài chính: Mong manh khi điểm ≥ | B29: 1 | C29: USER_FLOW: 1–4 mong manh; ≤0 sụp đổ.
A30: Quản trị: Đoàn kết khi điểm ≥ | B30: 3 | C30: USER_FLOW: ≥3.
A31: Quản trị: Chia rẽ chưa vỡ khi điểm ≥ | B31: 0 | C31: USER_FLOW: 0–2; <0 mất kiểm soát.
A32: Quản trị: đã mở HS-G | B32: 1
A33: Quản trị: mỗi lần mất Uy tín ở Màn 11 | B33: -1
A34: Quản trị: Tài chính rơi vào Sụp đổ | B34: -2
A35: Quản trị: chọn PD-D mà chưa mở HS-E | B35: -1
A36: Feedback band: High ≥ | B36: 80
A37: Feedback band: Mid ≥ | B37: 50
A39: Trọng số Counselor Score (tổng phải = 100%)
A40: Dimension | B40: Weight | C40: Cách tính (tối đa 100)
A41: Investigation | B41: 0.2 | C41: (Hồ sơ + CH1 + CH2 + synergy) ÷ điểm thông tin tối đa × 100
...

Sheet Lists
A1: Lists — nguồn dropdown (tự sinh, không sửa)
A3: Files | B3: Questions | C3: Final Q | D3: Diagnosis | E3: Treatment | F3: Timing | G3: Stakeholder | H3: Reassess decision
A4: =S2_Files!A5&" - "&S2_Files!B5 -> HS-A - Sales & Customer | B4: =S3_Questions!A5&" - "&S3_Questions!B5 -> CH1-A - Traffic giảm, e-commerce tăng — khách rời bỏ hay đổi kênh? | C4: =S5_FinalQ!A5&" - "&S5_FinalQ!B5 -> CH2-A - Khoản nào khó cắt nhất? | D4: =S6_Diagnosis!A5&" - "&S6_Diagnosis!B5 -> CD-A - Áp lực Cạnh tranh (Competitive Pressure) | E4: =S7_Treatment!A5&" - "&S7_Treatment!B5 -> PD-A - Invest to Compete | F4: =S8_Timing!A5&" - "&S8_Timing!B5 -> TG-A - Thực hiện ngay | G4: =S9_Stakeholders!A5&" - "&S9_Stakeholders!B5 -> GR-1 - Suppliers | H4: Keep
A5: =S2_Files!A6&" - "&S2_Files!B6 -> HS-B - Stores & Investment | B5: =S3_Questions!A6&" - "&S3_Questions!B6 -> CH1-B - Chương trình vốn nào bị trì hoãn lâu nhất? | C5: =S5_FinalQ!A6&" - "&S5_FinalQ!B6 -> CH2-B - Có thêm vốn thì dùng vào đâu? | D5: =S6_Diagnosis!A6&" - "&S6_Diagnosis!B6 -> CD-B - Nút thắt Vận hành (Operational Bottleneck) | E5: =S7_Treatment!A6&" - "&S7_Treatment!B6 -> PD-B - Deep Cost Cutting | F5: =S8_Timing!A6&" - "&S8_Timing!B6 -> TG-B - Sau holiday season | G5: =S9_Stakeholders!A6&" - "&S9_Stakeholders!B6 -> GR-2 - Employees | H5: Revise Diagnosis
A6: =S2_Files!A7&" - "&S2_Files!B7 -> HS-C - Liquidity | B6: =S3_Questions!A7&" - "&S3_Questions!B7 -> CH1-C - Holiday kém 10% thì thanh khoản ra sao? | C6: =S5_FinalQ!A7&" - "&S5_FinalQ!B7 -> CH2-C - Sao không đóng mạnh cửa hàng? | D6: =S6_Diagnosis!A7&" - "&S6_Diagnosis!B7 -> CD-C - Biểu hiện Thanh khoản tức thời (Liquidity Manifestation) | E6: =S7_Treatment!A7&" - "&S7_Treatment!B7 -> PD-C - Debt Restructuring | F6: =S8_Timing!A7&" - "&S8_Timing!B7 -> TG-C - Thử tái cấp vốn trước khi cam kết kế hoạch | G6: =S9_Stakeholders!A7&" - "&S9_Stakeholders!B7 -> GR-3 - Customers | H6: Revise Treatment
A7: =S2_Files!A8&" - "&S2_Files!B8 -> HS-D - Capital Structure & Leverage History | B7: =S3_Questions!A8&" - "&S3_Questions!B8 -> CH1-D - Khoản nợ nào đến hạn sớm nhất? | C7: =S5_FinalQ!A8&" - "&S5_FinalQ!B8 -> CH2-D - Amazon biến mất thì công ty khỏe chưa? | D7: =S6_Diagnosis!A8&" - "&S6_Diagnosis!B8 -> CD-D - Nguyên nhân Cấu trúc (Structural Driver) | E7: =S7_Treatment!A8&" - "&S7_Treatment!B8 -> PD-D - Asset Sale | F7: =S8_Timing!A8&" - "&S8_Timing!B8 -> TG-D - Chờ 6 tháng | G7: =S9_Stakeholders!A8&" - "&S9_Stakeholders!B8 -> GR-4 - Creditors | H7: Revise Both
A8: =S2_Files!A9&" - "&S2_Files!B9 -> HS-E - Product & Category Trends | B8: =S3_Questions!A9&" - "&S3_Questions!B9 -> CH1-E - Nhóm sản phẩm nào đang hoạt động tốt nhất? | C8: =S5_FinalQ!A9&" - "&S5_FinalQ!B9 -> CH2-E - Nếu loại bỏ được phần lớn áp lực nợ, đã giải quyết toàn bộ vấn đề chưa? | D8: =S6_Diagnosis!A9&" - "&S6_Diagnosis!B9 -> CD-E - Áp lực Danh mục Sản phẩm (Category Pressure) | E8: =S7_Treatment!A9&" - "&S7_Treatment!B9 -> PD-E - Bankruptcy Restructuring | G8: =S9_Stakeholders!A9&" - "&S9_Stakeholders!B9 -> GR-5 - Landlords
A9: =S2_Files!A10&" - "&S2_Files!B10 -> HS-F - Management Track Record | B9: =S3_Questions!A10&" - "&S3_Questions!B10 -> CH1-F - Ban lãnh đạo có đồng thuận không? | C9: =S5_FinalQ!A10&" - "&S5_FinalQ!B10 -> CH2-F - Lo nhất điều gì trong 12 tháng tới? | D9: =S6_Diagnosis!A10&" - "&S6_Diagnosis!B10 -> CD-F - Chẩn đoán Đa yếu tố (Multi-Factor Diagnosis) | E9: =S7_Treatment!A10&" - "&S7_Treatment!B10 -> PD-F - Combined Restructuring | G9: =S9_Stakeholders!A10&" - "&S9_Stakeholders!B10 -> GR-6 - Holiday Inventory
A10: =S2_Files!A11&" - "&S2_Files!B11 -> HS-G - Governance & Family | B10: =S3_Questions!A11&" - "&S3_Questions!B11 -> CH1-G - Có một điều khoản đặc biệt nào giữa Michael và nhà đầu tư bên ngoài không? | C10: =S5_FinalQ!A11&" - "&S5_FinalQ!B11 -> CH2-G - Nếu EBITDA giảm thêm 5%, điều gì xảy ra ngay lập tức? | G10: =S9_Stakeholders!A11&" - "&S9_Stakeholders!B11 -> GR-7 - Governance & Family

Sheet S2_Files
A1: Screen 2 — Hồ sơ chẩn đoán (chọn đúng 3 trong 7; 4 hồ sơ còn lại đóng vĩnh viễn)
A2: Points = giá trị thông tin khi mở đầy đủ (best 3 = HS-D + HS-G + HS-C = 40).
A4: ID | B4: Option (player sees) | C4: What it reveals | D4: Category | E4: Full-file pts | F4: Design note
A5: HS-A | B5: Sales & Customer | C5: SSS consolidated −1.4% (Domestic −1.3%, Intl −1.6%); Net sales $11.802bn → $11.540bn (−2.2%); e-commerce +11%. | D5: Supporting | E5: 8 | F5: Traffic yếu nhưng không phải kênh nào cũng giảm.
A6: HS-B | B6: Stores & Investment | C6: 6 chương trình đang tranh vốn hữu hạn: renovation, mobile & web, omnichannel, supply chain, customer experience, holiday inventory. | D6: Supporting | E6: 6 | F6: Áp lực CapEx dồn nén.
A7: HS-C | B7: Liquidity | C7: Cash $566m; Receivables $255m; Inventory $2.476bn; Current assets $3.389bn; PP&E $3.067bn. Cash cuối kỳ không phản ánh toàn bộ liquidity. | D7: Core | E7: 10 | F7: Thanh khoản / covenant.
A8: HS-D | B8: Capital Structure & Leverage History | C8: Total debt ~$4.8bn (secured ~$3.4bn); LBO 2015 $6.6bn; OCF trước 2015: $575m / $801m / $746m. 'Leverage cao nhưng đã tồn tại nhiều năm'. | D8: Core (gốc rễ) | E8: 15 | F8: Historical Financing Event — 2015.
A9: HS-E | B9: Product & Category Trends | C9: Toy ex-entertainment: Domestic +2.5% SSS, Consolidated +1.1%; entertainment/licensing yếu, phụ thuộc lịch phát hành bên ngoài. | D9: Supporting | E9: 5 | F9: Đồ chơi truyền thống vẫn có nhu cầu thật.
A10: HS-F | B10: Management Track Record | C10: 4 sáng kiến 3 năm qua: renovation pilot, cắt SG&A vòng 1, digital & app, tái cấu trúc một phần nợ quốc tế — mỗi thứ chỉ xử lý một phần. | D10: Supporting | E10: 7 | F10: Chưa sáng kiến nào đủ lớn.
A11: HS-G | B11: Governance & Family | C11: Cổ phần Anderson 78%; thỏa thuận Michael–Houndstooth (quyền mua ưu tiên nếu Adj. EBITDA giảm thêm 5%); Richard chào bán tài sản quốc tế; thư luật sư của Michael. | D11: Core (bí mật nền) | E11: 15 | F11: Chỉ HS-G xác nhận đầy đủ bí mật nền.

Sheet S3_Questions
A1: Screen 3 — Câu hỏi bổ sung (chọn đúng 2 trong 7)
A2: Points = giá trị BỀ MẶT nếu khu vực CHƯA mở hồ sơ đầy đủ. Nếu khu vực đã mở hồ sơ, câu hỏi chỉ củng cố chi tiết nhỏ (=1, xem M1 và Config).
A4: ID | B4: Option (player sees) | C4: What it reveals | D4: Area | E4: Surface pts | F4: Design note
A5: CH1-A | B5: Traffic giảm, e-commerce tăng — khách rời bỏ hay đổi kênh? | C5: Phần lớn đổi kênh; biên online thấp hơn store. Tin đồn tái cấu trúc gia đình khiến một phần khách chuyển sang đối thủ. | D5: Khu vực HS-A | E5: 3 | F5: Bề mặt của HS-A.
A6: CH1-B | B6: Chương trình vốn nào bị trì hoãn lâu nhất? | C6: Store renovation — gác 3 năm liên tiếp; Richard nhiều lần bỏ phiếu trì hoãn vì đang đàm phán bán tài sản riêng. | D6: Khu vực HS-B | E6: 2 | F6: Bề mặt của HS-B.
A7: CH1-C | B7: Holiday kém 10% thì thanh khoản ra sao? | C7: Vẫn đủ cash hoạt động, nhưng biên an toàn covenant mỏng đi đáng kể. | D7: Khu vực HS-C | E7: 4 | F7: Bề mặt của HS-C.
A8: CH1-D | B8: Khoản nợ nào đến hạn sớm nhất? | C8: Một phần secured notes đáo hạn trong 18 tháng; EBITDA trigger của Houndstooth có thể phát sinh sớm hơn. | D8: Khu vực HS-D | E8: 6 | F8: Bề mặt của HS-D (hé lộ Houndstooth).
A9: CH1-E | B9: Nhóm sản phẩm nào đang hoạt động tốt nhất? | C9: Đồ chơi truyền thống nhưng quy mô nhỏ; Richard đang âm thầm rao bán mảng này. | D9: Khu vực HS-E | E9: 2 | F9: Bề mặt của HS-E.
A10: CH1-F | B10: Ban lãnh đạo có đồng thuận không? | C10: Không — Michael đã mời riêng luật sư chuyên 'chuyển giao quyền lực'. | D10: Khu vực HS-F/G | E10: 3 | F10: Bề mặt của HS-F.
A11: CH1-G | B11: Có một điều khoản đặc biệt nào giữa Michael và nhà đầu tư bên ngoài không? | C11: Có một thỏa thuận có điều kiện có thể ảnh hưởng đến quyền sở hữu của gia đình, nhưng chi tiết cụ thể (điều kiện kích hoạt, đối tác) chưa rõ — cần xem hồ sơ đầy đủ. | D11: Khu vực HS-G | E11: 3 | F11: Bề mặt của HS-G — ĐÃ GIẢM 6→3đ và bớt chi tiết (bản sửa USER_FLOW) để việc mở HS-G vẫn có giá trị.

Sheet S5_FinalQ
A1: Screen 5 — Câu hỏi cuối (chọn đúng 1 trong 7)
A2: Points = điểm phản tư cơ bản; cộng thêm điểm từ M2 nếu hồ sơ liên quan đã mở; tổng bị chặn ở Config (fq_cap).
A4: ID | B4: Option (player sees) | C4: What it reveals | D4: Category | E4: Base pts | F4: Design note
A5: CH2-A | B5: Khoản nào khó cắt nhất? | C5: Nghĩa vụ tài chính có thể refinance nhưng không biến mất; Michael thúc cắt marketing mạnh hơn CFO khuyến nghị. | D5: Phản tư | E5: 3 | F5: Nghiêng về chi phí/nợ.
A6: CH2-B | B6: Có thêm vốn thì dùng vào đâu? | C6: Digital, fulfillment, renovation. Nếu Houndstooth thắng, phần lớn đầu tư này dừng ngay. | D6: Phản tư | E6: 3 | F6: Nghiêng về đầu tư cạnh tranh.
A7: CH2-C | B7: Sao không đóng mạnh cửa hàng? | C7: Một số nên đóng nhưng cắt sâu làm nhỏ sales base; nhiều hợp đồng thuê do Richard đứng tên cá nhân. | D7: Phản tư | E7: 3 | F7: Nghiêng về mạng lưới cửa hàng.
A8: CH2-D | B8: Amazon biến mất thì công ty khỏe chưa? | C8: Không — áp lực nội bộ (gia đình, nợ) vẫn còn nguyên. | D8: Phản tư | E8: 2 | F8: Loại giả thuyết cạnh tranh.
A9: CH2-E | B9: Nếu loại bỏ được phần lớn áp lực nợ, đã giải quyết toàn bộ vấn đề chưa? | C9: Không — vẫn phải xử lý store base và cạnh tranh; hết nợ thì Michael/Richard chuyển sang đấu tố quyền kiểm soát. | D9: Phản tư | E9: 4 | F9: Nghiêng về giả thuyết hỗn hợp.
A10: CH2-F | B10: Lo nhất điều gì trong 12 tháng tới? | C10: Liquidity & refinancing. David: Michael sẽ dùng khoản lỗ để thuyết phục cổ đông nhỏ lẻ rằng tôi hết năng lực. | D10: Phản tư | E10: 4 | F10: Thanh khoản + quản trị.
A11: CH2-G | B11: Nếu EBITDA giảm thêm 5%, điều gì xảy ra ngay lập tức? | C11: Điều khoản Houndstooth kích hoạt tự động — không cần họp hội đồng (đầy đủ nếu đã mở HS-G). | D11: Phản tư | E11: 4 | F11: Giá trị cao nhất khi đã mở HS-G.

Sheet M1_File_x_Q
A1: Matrix M1 — Hồ sơ (Màn 2) × Câu hỏi bổ sung (Màn 3): giá trị thông tin tăng thêm
A2: Cùng khu vực (HS-X × CH1-X) = chỉ củng cố chi tiết nhỏ (=1). Khác khu vực = điểm bề mặt của câu hỏi (S3). Với mỗi câu hỏi, hệ thống lấy MIN qua 3 hồ sơ đã mở → nếu khu vực đã mở thì chỉ còn =1.
A4: Hồ sơ ↓ / Câu hỏi → | C4: Traffic giảm, e-commerce tăng — khách rời bỏ hay đổi kê | D4: Chương trình vốn nào bị trì hoãn lâu nhất? | E4: Holiday kém 10% thì thanh khoản ra sao? | F4: Khoản nợ nào đến hạn sớm nhất? | G4: Nhóm sản phẩm nào đang hoạt động tốt nhất? | H4: Ban lãnh đạo có đồng thuận không? | I4: Có một điều khoản đặc biệt nào giữa Michael và nhà đầu
A5: ID | B5: Option | C5: CH1-A | D5: CH1-B | E5: CH1-C | F5: CH1-D | G5: CH1-E | H5: CH1-F | I5: CH1-G
A6: HS-A | B6: Sales & Customer | C6: =IF(RIGHT($A6,1)=RIGHT(C$5,1),Config!$B$5,INDEX(S3_Questions!$E$5:$E$11,MATCH(C$5,S3_Questions!$A$5:$A$11,0))) -> 1 | D6: =IF(RIGHT($A6,1)=RIGHT(D$5,1),Config!$B$5,INDEX(S3_Questions!$E$5:$E$11,MATCH(D$5,S3_Questions!$A$5:$A$11,0))) -> 2 | E6: =IF(RIGHT($A6,1)=RIGHT(E$5,1),Config!$B$5,INDEX(S3_Questions!$E$5:$E$11,MATCH(E$5,S3_Questions!$A$5:$A$11,0))) -> 4 | F6: =IF(RIGHT($A6,1)=RIGHT(F$5,1),Config!$B$5,INDEX(S3_Questions!$E$5:$E$11,MATCH(F$5,S3_Questions!$A$5:$A$11,0))) -> 6 | G6: =IF(RIGHT($A6,1)=RIGHT(G$5,1),Config!$B$5,INDEX(S3_Questions!$E$5:$E$11,MATCH(G$5,S3_Questions!$A$5:$A$11,0))) -> 2 | H6: =IF(RIGHT($A6,1)=RIGHT(H$5,1),Config!$B$5,INDEX(S3_Questions!$E$5:$E$11,MATCH(H$5,S3_Questions!$A$5:$A$11,0))) -> 3 | I6: =IF(RIGHT($A6,1)=RIGHT(I$5,1),Config!$B$5,INDEX(S3_Questions!$E$5:$E$11,MATCH(I$5,S3_Questions!$A$5:$A$11,0))) -> 3
